Workbook
Name Location: #REF!
Name Location: #REF!
Name Portfolios: #REF!
Name Portfolios: #REF!
Name UST_Project_ID: #REF!
Name UST_Project_ID: #REF!

Sheet README
A1: TrioEdX — Pricing & Revenue-Share Model v5
A2: Single global price, splits on Net Revenue. v5 simplifies books, flattens tier 3 to 17%, and rewrites the break-even block.
A4: WHAT CHANGED IN v3
A5: 1. Subscription scope | B5: All-access now explicitly covers self-paced catalogue courses ONLY. Certificates, degree
B6: courses, group cohorts and 1-on-1 are excluded and sold separately. Inclusion is opt-in per
B7: course. See 'Subscription Scope'.
A8: 2. Course referral rate | B8: Raised from 15% to 18% (Assumptions). Now clears cost at every price on the list.
A9: 3. Tutoring tier 3 | B9: Tier 3 is a FLAT 17% from v5. The $18/hr floor and the 20% below-floor branch are retired — see 'Change Log'.
A10: 4. Revenue basis | B10: Prices are tax-inclusive. Every split is computed on NET REVENUE = gross less tax less
B11: processing — not on the gross price. This is the biggest structural change; see below.
A12: 5. Coupon funding | B12: The platform fee is charged on the PRE-discount amount, so an instructor funds their own
B13: discount as the rule always intended.
A14: 6. Group class top-up | B14: NOT implemented, by decision. The no-minimum risk stands unmitigated — logged on the
B15: Group Classes tab as an accepted open risk so it is not lost.
A16: Lesson packages | B16: Added. Two options only: pay-as-you-go, and a 10-hour pack at 5% off.
A18: WHAT THE NET REVENUE BASIS MEANS
B19: Tax and payment processing come off the top, before anyone's share is calculated. Whatever
B20: is left is Net Revenue, and that is what gets split.
B22: Instructors earn less than under the old gross-price basis — on a $79 organic sale, $34.33
B23: instead of $39.50. That is correct: tax was never anyone's revenue to share. But it is a real
B24: change and it must be explained in the instructor agreement before anyone signs.
B26: It also means the platform no longer absorbs processing alone — it is shared in proportion.
B27: This is the same shape as the pass-through structure, and it is what Tutor LMS supports
B28: natively via its Fees setting, which makes it cheaper to build as well as fairer.
A30: TABS
A31: Assumptions | B31: Payment rates, tax basis, cost stack, take-rate levers. Start here.
A32: Price List | B32: One price per product.
A33: Subscription Scope | B33: NEW. What all-access includes and excludes, and the opt-in mechanic.
A34: Payment Economics | B34: Cost per ticket and minimum viable price at each take rate.
A35: 1-on-1 Tutoring | B35: Rate bands, the conditional tier-3 floor, and the full waterfall.
A36: Lesson Packages | B36: NEW. Pay-as-you-go vs the 10-hour pack, plus the three rules packages need.
A37: Group Classes | B37: Cohort economics. No-minimum risk logged as accepted.
A38: Courses | B38: Four channels at the new 18% referral rate, on the Net Revenue basis.
A39: Subscription | B39: Pooled payout, narrowed to the opted-in catalogue.
A40: Books & Authors | B40: Two author routes: ebook, and commissioned textbook.
A41: Take Rate Compare | B41: Scenario table is illustrative only — it does not use the model's live rates.
A42: Benchmarks | B42: Sourced competitor rates and platform limits.
A43: Change Log | B43: Every version, newest at the top.
A45: WHAT CHANGED IN v4
A46: 1. Subscription term | B46: The monthly plan now carries a 6-MONTH MINIMUM, billed as one charge. $114 committed is 1.44 standard courses, so all-access no longer undercuts a single $79 course. A 3-month term ($57) would not have cleared it.
...

Sheet Assumptions
A1: Assumptions
A2: WooCommerce / WooPayments, US merchant of record. Prices are tax-inclusive.
A4: PAYMENT PROCESSING — WOOCOMMERCE
A5: Gateway component | B5: WooPayments (used) | C5: Stripe direct (refernece only) | D5: Note
A6: Domestic card rate | B6: 0.029 | C6: 0.029 | D6: WooCommerce itself takes 0%.
A7: International card surcharge | B7: 0.01 | C7: 0.015 | D7: Applies when the buyer's card is issued outside the US.
A8: Currency conversion | B8: 0.02 | C8: 0.01 | D8: WooPayments charges 2%.
A9: Fixed fee per transaction | B9: 0.3 | C9: 0.3 | D9: Regressive — this is why the 10-pack is cheaper to process than 10 lessons.
A10: Dispute / chargeback fee | B10: 15 | C10: 15 | D10: WooPayments refunds it if you win; Stripe direct does not.
A12: Share of sales on a foreign-issued card | B12: 0.6
A13: BLENDED processing rate | B13: =B6*(1-B12)+(B6+B7+B8)*B12 -> 0.047
A15: TAX & REVENUE BASIS [NEW IN v3 — closes audit issue 4]
A16: Prices displayed are tax-inclusive | B16: YES | D16: What the buyer sees is what they pay. One number on every card, in every currency, everywhere.
A17: Blended tax rate across the customer base | B17: 0.08 | D17: A weighted average: many US sales carry no VAT, EU sales carry 19-25%, UK 20%. Re-check as the mix shifts.
A18: SPLITS ARE COMPUTED ON | B18: Net Revenue | D18: Net Revenue = gross less tax less payment processing. Tax was never anyone's revenue to share, and processing is now shared in proportion rather than absorbed by TrioEdX alone.
A19: Instructor impact — MUST be in the agreement | B19: see note | D19: On a $79 organic sale an instructor now earns $34.33 instead of $39.50. Lower, and correct — but it has to be explained before anyone signs, not after their first payout.
A21: COST STACK
A22: Deducted BEFORE the split (from gross, to reach Net Revenue):
A23: Cost line | B23: Courses | C23: Tutoring | D23: Note
A24: Tax (blended) | B24: =$B$17 -> 0.08 | C24: =$B$17 -> 0.08 | D24: Remitted to tax authorities. Never revenue.
A25: Payment processing | B25: =$B$13 -> 0.047 | C25: =$B$13-0.004 -> 0.043 | D25: Plus the $0.30 fixed fee, applied per transaction on every tab.
A26: Total deducted before the split | B26: =SUM(B24:B25) -> 0.127 | C26: =SUM(C24:C25) -> 0.123
A28: TrioEdX's OWN costs (paid out of our share, after the split):
A29: Cost line | B29: Courses | C29: Tutoring | D29: Note
A30: Instructor payout & FX (Wise/Payoneer) | B30: 0.015 | C30: 0.015 | D30: Neither Stripe nor WooPayments pays out to Pakistan.
A31: Refunds & chargeback reserve | B31: 0.04 | C31: 0.02 | D31: Self-paced courses refund far more than booked live sessions.
A32: Video, hosting, LMS infrastructure | B32: 0.02 | C32: 0.03 | D32: Live sessions carry per-minute video cost.
A33: Support, trust & safety, content QA | B33: 0.03 | C33: 0.025 | D33: Human cost.
A34: Total TrioEdX own costs | B34: =SUM(B30:B33) -> 0.105 | C34: =SUM(C30:C33) -> 0.09 | D34: Expressed as a % of the GROSS price — these scale with the transaction, not with our share.
A36: FIXED MONTHLY COST
A37: Cost line | B37: $ / month | D37: Note
A38: Hosting / VPS / CDN | B38: 180 | D38: HostGator Snappy 4000 VPS class + CDN.
A39: Tutor LMS Pro (Business) | B39: 33.25 | D39: $399/yr.
A40: WooCommerce Subscriptions | B40: 23.25 | D40: $279/yr.
A41: WooCommerce Bookings | B41: 20.75 | D41: $249/yr, or zero if the custom booking plugin is kept.
A42: WooCommerce EU VAT Number | B42: 3.25 | D42: $39/yr. Now essential — tax-inclusive pricing needs correct VAT determination.
A43: Quaderno (cross-border VAT/GST) | B43: 49 | D43: $49/mo. Also now essential for the same reason.
A44: Elementor Pro + other licences | B44: 15 | D44: Theme and page-builder licences.
A45: Video infrastructure base | B45: 150 | D45: Zoom/LiveKit committed minimum.
A46: Tools, analytics, accounting | B46: 200 | D46: Bookkeeping, support desk.
...

Sheet Price List
A1: Price List — one price, everywhere
A2: USD, tax-inclusive. What the buyer sees is what they pay.
A4: Product | B4: Price | C4: Net Revenue | D4: Our net @50% | E4: Margin | F4: In the subscription?
A5: Micro-course (2-4 hrs) | B5: 29 | C5: =B5-B5*Assumptions!$B$17-(B5*Assumptions!$B$25+Assumptions!$B$9) -> 25.017 | D5: =C5*Assumptions!$B$62-B5*Assumptions!$B$34 -> 9.4635 | E5: =IF(B5=0,0,D5/B5) -> 0.32632759 | F5: YES — if the instructor opts in
A6: Standard course (8-15 hrs) | B6: 79 | C6: =B6-B6*Assumptions!$B$17-(B6*Assumptions!$B$25+Assumptions!$B$9) -> 68.667 | D6: =C6*Assumptions!$B$62-B6*Assumptions!$B$34 -> 26.0385 | E6: =IF(B6=0,0,D6/B6) -> 0.32960127 | F6: YES — if the instructor opts in
A7: Professional certificate (4-6 courses) | B7: 299 | C7: =B7-B7*Assumptions!$B$17-(B7*Assumptions!$B$25+Assumptions!$B$9) -> 260.727 | D7: =C7*Assumptions!$B$62-B7*Assumptions!$B$34 -> 98.9685 | E7: =IF(B7=0,0,D7/B7) -> 0.33099833 | F7: NO — sold separately
A8: Associate-degree course (3 credits, supported) | B8: 249 | C8: =B8-B8*Assumptions!$B$17-(B8*Assumptions!$B$25+Assumptions!$B$9) -> 217.077 | D8: =C8*Assumptions!$B$62-B8*Assumptions!$B$34 -> 82.3935 | E8: =IF(B8=0,0,D8/B8) -> 0.33089759 | F8: NO — sold separately
A9: Full associate degree (60 credits = 20 courses) | B9: =B8*20 -> 4980 | C9: =B9-B9*Assumptions!$B$17-(B9*Assumptions!$B$25+Assumptions!$B$9) -> 4347.24 | D9: =C9*Assumptions!$B$62-B9*Assumptions!$B$34 -> 1650.72 | E9: =IF(B9=0,0,D9/B9) -> 0.33146988 | F9: NO — sold separately
A10: Group class — per seat, per session | B10: 12 | C10: =B10-B10*Assumptions!$B$17-(B10*Assumptions!$B$25+Assumptions!$B$9) -> 10.176 | D10: =C10*Assumptions!$B$62-B10*Assumptions!$B$34 -> 3.828 | E10: =IF(B10=0,0,D10/B10) -> 0.319 | F10: NO — live, sold separately
A11: 1-on-1 tutoring | B11: tutor sets | F11: NO — live, sold separately
A12: All-access subscription ($/month, 6-month minimum term) | B12: 19 | C12: =B12-B12*Assumptions!$B$17-(B12*Assumptions!$B$25+Assumptions!$B$9) -> 16.287 | D12: =C12*Assumptions!$B$62-B12*Assumptions!$B$34 -> 6.1485 | E12: =IF(B12=0,0,D12/B12) -> 0.32360526 | F12: — (see Subscription)
A13: All-access subscription ($/year) | B13: 180 | C13: =B13-B13*Assumptions!$B$17-(B13*Assumptions!$B$25+Assumptions!$B$9) -> 156.84 | D13: =C13*Assumptions!$B$62-B13*Assumptions!$B$34 -> 59.52 | E13: =IF(B13=0,0,D13/B13) -> 0.33066667 | F13: —
A15: The last column is new in v3 and is the single most important thing on this sheet — see 'Subscription Scope'.
A17: v4: the monthly plan now carries a 6-MONTH MINIMUM TERM. $19 x 6 = $114 committed, which is 1.44 standard courses.
A18: At no minimum ($19) or a three-month minimum ($57) the subscription was cheaper than a single $79 course, so it
A19: cannibalised the catalogue it was meant to feed. Six months is the shortest term that clears one course price.
A20: The term is billed as ONE charge, not six monthly ones.

Sheet Subscription Scope
A1: What All-Access Includes [NEW IN v3 — closes audit issue 1]
A2: The subscription was undercutting the whole catalogue because nothing defined its boundary. This is the boundary.
A4: THE PROBLEM THIS FIXES
A5: • At $19/month with no stated limit, a student could reasonably assume all-access covered everything — certificates, degree courses, group classes, even tutoring.
A6: • On that reading, $180/year of subscription replaced $299 of certificate, $79 courses and $96 group cohorts. Nothing else was worth buying.
A7: • An instructor also had no way to know whether their course was in the pool or sold directly, and the two pay very differently.
A9: THE BOUNDARY
A10: Product | B10: In all-access? | C10: How it is sold | D10: Why
A11: Micro-courses | B11: YES | C11: Included, opt-in | D11: Zero marginal cost. These are the funnel.
A12: Standard self-paced courses | B12: YES | C12: Included, opt-in | D12: Zero marginal cost. The core of the catalogue.
A13: Professional certificates | B13: NO | C13: One-off purchase | D13: Assessed, credentialed, and carries a real per-issue cost.
A14: Associate-degree courses | B14: NO | C14: One-off or payment plan | D14: Instructor-supported and accredited. Not a catalogue item.
A15: Full associate degree | B15: NO | C15: Payment plan | D15: Two-year programme; cannot be consumed in a $19 month.
A16: Group classes / cohorts | B16: NO | C16: Per seat | D16: Live teaching. A tutor's hour has real cost.
A17: 1-on-1 tutoring | B17: NO | C17: Per hour or 10-pack | D17: Live teaching. Never bundled.
A18: Books / ebooks | B18: NO | C18: One-off purchase | D18: Author royalty is per unit sold.
A20: Everything marked NO must say so on its product page, or the boundary will not hold.
A22: THE OPT-IN MECHANIC
A23: • Inclusion in the subscription is OPT-IN per course, chosen by the instructor, and reversible with 30 days' notice.
A24: • Before opting in, the instructor sees an estimate: 'based on the current pool rate, a course like yours earned roughly $X last month'.
A25: • The pool share (currently 50% of net subscription revenue) is guaranteed in writing not to fall for a course already enrolled. Udemy's biggest instructor grievance was a share that moved after the fact.
A26: • Free courses are excluded from the pool entirely — they earn nothing from it and cost nothing to it.
A28: THE NUMBER AN INSTRUCTOR WILL CHECK
A29: One direct organic sale of a $79 course pays the instructor | B29: =('Price List'!C6)*(1-Assumptions!$B$62) -> 34.3335
A30: Pool rate per 1,000 qualified minutes | B30: =Subscription!B26 -> 9.468875
A31: Minutes of consumption needed to match one direct sale | B31: =IF(B30=0,0,B29/B30*1000) -> 3625.9323
A32: Same, expressed in hours | B32: =IF(B30=0,0,B29/B30*1000/60) -> 60.432206
A33: Show this figure honestly on the opt-in screen. An instructor who discovers it later opts out and tells the others.

Sheet Payment Economics
A1: Payment Economics
A2: Cost per ticket, and the minimum price each take rate can carry.
A4: Ticket | B4: Tax | C4: Processing | D4: Net Revenue | E4: NR as % of gross | F4: Product
A5: 12 | B5: =A5*Assumptions!$B$17 -> 0.96 | C5: =A5*Assumptions!$B$25+Assumptions!$B$9 -> 0.864 | D5: =A5-B5-C5 -> 10.176 | E5: =D5/A5 -> 0.848 | F5: group class seat
A6: 19 | B6: =A6*Assumptions!$B$17 -> 1.52 | C6: =A6*Assumptions!$B$25+Assumptions!$B$9 -> 1.193 | D6: =A6-B6-C6 -> 16.287 | E6: =D6/A6 -> 0.85721053 | F6: subscription month
A7: 29 | B7: =A7*Assumptions!$B$17 -> 2.32 | C7: =A7*Assumptions!$B$25+Assumptions!$B$9 -> 1.663 | D7: =A7-B7-C7 -> 25.017 | E7: =D7/A7 -> 0.86265517 | F7: micro-course
A8: 30 | B8: =A8*Assumptions!$B$17 -> 2.4 | C8: =A8*Assumptions!$B$25+Assumptions!$B$9 -> 1.71 | D8: =A8-B8-C8 -> 25.89 | E8: =D8/A8 -> 0.863 | F8: 1-on-1 hour
A9: 79 | B9: =A9*Assumptions!$B$17 -> 6.32 | C9: =A9*Assumptions!$B$25+Assumptions!$B$9 -> 4.013 | D9: =A9-B9-C9 -> 68.667 | E9: =D9/A9 -> 0.86920253 | F9: standard course
A10: 180 | B10: =A10*Assumptions!$B$17 -> 14.4 | C10: =A10*Assumptions!$B$25+Assumptions!$B$9 -> 8.76 | D10: =A10-B10-C10 -> 156.84 | E10: =D10/A10 -> 0.87133333 | F10: annual subscription
A11: 285 | B11: =A11*Assumptions!$B$17 -> 22.8 | C11: =A11*Assumptions!$B$25+Assumptions!$B$9 -> 13.695 | D11: =A11-B11-C11 -> 248.505 | E11: =D11/A11 -> 0.87194737 | F11: 10-hour package
A12: 299 | B12: =A12*Assumptions!$B$17 -> 23.92 | C12: =A12*Assumptions!$B$25+Assumptions!$B$9 -> 14.353 | D12: =A12-B12-C12 -> 260.727 | E12: =D12/A12 -> 0.87199666 | F12: certificate
A14: VARIABLE-COST BREAK-EVEN — and what each sale actually contributes [RETITLED IN v5]
A15: At this take rate | B15: Variable-cost break-even ticket | C15: Reference sale | D15: Contribution per transaction | E15: Sales / month to cover fixed cost | F15: Reading
A16: 18% — course referral (v3) | B16: =IF(Assumptions!$B$61*(1-Assumptions!$B$17-Assumptions!$B$25)-Assumptions!$B$34<=0,"never profitable",Assumptions!$B$61*Assumptions!$B$9/(Assumptions!$B$61*(1-Assumptions!$B$17-Assumptions!$B$25)-Assumptions!$B$34)) -> 1.0356732 | C16: a $79 standard course, referral channel | D16: =Courses!$F$8 -> 4.06506 | E16: =IF($D16<=0,"n/a",Assumptions!$B$49/$D16) -> 830.12305 | F16: Break-even is variable cost only. The contribution column is what the sale is actually worth.
A17: 22% — group class | B17: =IF(Assumptions!$B$60*(1-Assumptions!$B$17-Assumptions!$C$25)-Assumptions!$C$34<=0,"never profitable",Assumptions!$B$60*Assumptions!$B$9/(Assumptions!$B$60*(1-Assumptions!$B$17-Assumptions!$C$25)-Assumptions!$C$34)) -> 0.64115018 | C17: one cohort seat — 8 sessions at $12 | D17: ='Group Classes'!$E$9 -> 9.81624 | E17: =IF($D17<=0,"n/a",Assumptions!$B$49/$D17) -> 343.76706 | F17: Break-even is variable cost only. The contribution column is what the sale is actually worth.
A18: 25% — tutoring tier 1 | B18: =IF(Assumptions!$B$53*(1-Assumptions!$B$17-Assumptions!$C$25)-Assumptions!$C$34<=0,"never profitable",Assumptions!$B$53*Assumptions!$B$9/(Assumptions!$B$53*(1-Assumptions!$B$17-Assumptions!$C$25)-Assumptions!$C$34)) -> 0.58027079 | C18: one tutoring hour at $30 | D18: ='1-on-1 Tutoring'!$F$21 -> 3.8025 | E18: =IF($D18<=0,"n/a",Assumptions!$B$49/$D18) -> 887.44247 | F18: Break-even is variable cost only. The contribution column is what the sale is actually worth.
A19: 50% — course organic | B19: =IF(Assumptions!$B$62*(1-Assumptions!$B$17-Assumptions!$B$25)-Assumptions!$B$34<=0,"never profitable",Assumptions!$B$62*Assumptions!$B$9/(Assumptions!$B$62*(1-Assumptions!$B$17-Assumptions!$B$25)-Assumptions!$B$34)) -> 0.45248869 | C19: a $79 standard course, organic channel | D19: =Courses!$F$9 -> 26.0385 | E19: =IF($D19<=0,"n/a",Assumptions!$B$49/$D19) -> 129.59656 | F19: Break-even is variable cost only. The contribution column is what the sale is actually worth.
A21: Break-even prices are far lower than in v2 because tax and the $0.30 fixed fee now come off BEFORE the split — so TrioEdX bears only its share of them, not all of them. This is the pass-through effect, and it is why 18% works where 15% on the gross basis did not.
A23: HOW TO READ THESE TWO COLUMNS
A24: • The break-even column answers one narrow question: below what price does this transaction lose money on variable cost alone?
A25: It is NOT a pricing floor. A $1.04 break-even does not make a $2 product sensible — at $2 the sale contributes cents.
A26: • The contribution column is the number that matters: what one sale leaves after tax, processing, the counterparty's share
A27: and TrioEdX's own costs. The last column turns that into the only question a young business has to answer —
A28: how many of these do we need each month before fixed cost is paid?
A29: • Fixed cost is Assumptions B49. Nothing above that line is profit; it is a hurdle every revenue line clears together.

Sheet 1-on-1 Tutoring
A1: 1-on-1 Tutoring Economics
A2: Tier 3 is a flat rate from v5. The rate guardrails below are advisory bands, not enforced prices.
A4: RATE GUARDRAILS — banded by the TUTOR's cost base
A5: Tutor band | B5: Floor $/hr | C5: Typical low | D5: Typical high | E5: Ceiling $/hr | G5: Note
A6: Global / high-cost market tutor | B6: 18 | C6: 30 | D6: 55 | E6: 150 | G6: Benchmark: math/CS median ~EUR 25-30/hr.
A7: Emerging-market tutor | B7: 6 | C7: 8 | D7: 20 | E7: 60 | G7: With zones gone, this band is the only thing keeping TrioEdX affordable in low-income markets.
A8: STEM / programming premium | G8: Apply +15-20% to the band above.
A11: TIER 3 IS NOW A FLAT RATE [CHANGED IN v5 — the floor is retired]
A12: • Tier 3 is a flat 17% at 300+ cumulative hours. The $18/hr floor and the 20% below-floor branch are both retired.
A13: • The floor rested on a break-even of about $17.65/hr — a v2 figure, from when splits were computed on the GROSS price.
A14: On the Net Revenue basis 17% breaks even near $0.86/hr, so the whole rate band is profitable and the floor solved nothing.
A15: • At $30/hr, 17% keeps TrioEdX $1.72 (5.7%) rather than $1.20 (4.0%) — about 1,960 tier-3 hours a month to cover fixed cost, from 2,808.
A17: Tutor's hourly rate | B17: 30 | G17: Change this to test a tutor at any rate; the tier-3 row switches automatically.
A18: Tier 3 rate (flat) | B18: =Assumptions!$B$55 -> 0.17 | G18: v5: no longer conditional on the tutor's hourly rate.
A20: Tier | B20: Take | C20: Student pays | D20: Net Revenue | E20: Tutor keeps | F20: TrioEdX net | G20: Margin %
A21: Tier 1 — hours 0-50 | B21: =Assumptions!$B$53 -> 0.25 | C21: =$B$17 -> 30 | D21: =C21-C21*Assumptions!$B$17-(C21*Assumptions!$C$25+Assumptions!$B$9) -> 26.01 | E21: =D21*(1-B21) -> 19.5075 | F21: =D21*B21-C21*Assumptions!$C$34 -> 3.8025 | G21: =IF(C21=0,0,F21/C21) -> 0.12675
A22: Tier 2 — hours 51-300 | B22: =Assumptions!$B$54 -> 0.2 | C22: =$B$17 -> 30 | D22: =C22-C22*Assumptions!$B$17-(C22*Assumptions!$C$25+Assumptions!$B$9) -> 26.01 | E22: =D22*(1-B22) -> 20.808 | F22: =D22*B22-C22*Assumptions!$C$34 -> 2.502 | G22: =IF(C22=0,0,F22/C22) -> 0.0834
A23: Tier 3 — hours 300+ (flat) | B23: =$B$18 -> 0.17 | C23: =$B$17 -> 30 | D23: =C23-C23*Assumptions!$B$17-(C23*Assumptions!$C$25+Assumptions!$B$9) -> 26.01 | E23: =D23*(1-B23) -> 21.5883 | F23: =D23*B23-C23*Assumptions!$C$34 -> 1.7217 | G23: =IF(C23=0,0,F23/C23) -> 0.05739
A24: Trial lesson (30 min, half rate) | B24: =Assumptions!$B$58 -> 0.5 | C24: =$B$17*0.5 -> 15 | D24: =C24-C24*Assumptions!$B$17-(C24*Assumptions!$C$25+Assumptions!$B$9) -> 12.855 | E24: =D24*(1-B24) -> 6.4275 | F24: =D24*B24-C24*Assumptions!$C$34 -> 5.0775 | G24: =IF(C24=0,0,F24/C24) -> 0.3385
A26: Tutor keeps is now a share of NET revenue, so it is lower than the old gross-basis figure. Tax and processing came off the top first — see the Assumptions note.

Sheet Lesson Packages
A1: Lesson Packages [NEW IN v3]
A2: Two options only: pay as you go, or a 10-hour pack at 5% off. Nothing else is offered.
A4: Tutor's hourly rate | B4: 30
A5: Tier applied (tier 1 shown) | B5: =Assumptions!$B$53 -> 0.25
B7: A — Pay as you go | C7: B — 10-hour pack | D7: Difference | E7: Note
A8: Hours purchased | B8: =10 -> 10 | C8: =10 -> 10 | E8: Same teaching either way — only the payment differs.
A9: Transactions | B9: =10 -> 10 | C9: =1 -> 1 | E9: Ten $0.30 fixed fees, or one. This is where the discount is funded from.
A10: Discount | B10: =0 -> 0 | C10: =Assumptions!$B$59 -> 0.05 | E10: 5%, as decided.
A11: Student pays | B11: =$B$4*B8 -> 300 | C11: =$B$4*C8*(1-C10) -> 285 | D11: =C11-B11 -> -15 | E11: The student's saving.
A12: Less: tax | B12: =-B11*Assumptions!$B$17 -> -24 | C12: =-C11*Assumptions!$B$17 -> -22.8 | D12: =C12-B12 -> 1.2
A13: Less: processing | B13: =-(B11*Assumptions!$C$25+Assumptions!$B$9*B9) -> -15.9 | C13: =-(C11*Assumptions!$C$25+Assumptions!$B$9*C9) -> -12.555 | D13: =C13-B13 -> 3.345 | E13: Ten fixed fees vs one — a $2.70 saving that largely pays for the discount.
A14: Net Revenue | B14: =SUM(B11:B13) -> 260.1 | C14: =SUM(C11:C13) -> 249.645 | D14: =C14-B14 -> -10.455
A15: Tutor keeps | B15: =B14*(1-$B$5) -> 195.075 | C15: =C14*(1-$B$5) -> 187.23375 | D15: =C15-B15 -> -7.84125 | E15: The tutor funds the discount at the standard take rate.
A16: TrioEdX share | B16: =B14*$B$5 -> 65.025 | C16: =C14*$B$5 -> 62.41125 | D16: =C16-B16 -> -2.61375
A17: Less: our own costs | B17: =-B11*Assumptions!$C$34 -> -27 | C17: =-C11*Assumptions!$C$34 -> -25.65 | D17: =C17-B17 -> 1.35
A18: TrioEdX NET | B18: =B16+B17 -> 38.025 | C18: =C16+C17 -> 36.76125 | D18: =C18-B18 -> -1.26375 | E18: Nearly identical, because the fixed-fee saving offsets the discount.
A20: Read the Difference column: the student saves real money, TrioEdX is close to neutral, and the tutor funds the discount. If you would rather share it, drop the package take rate by two points — the lever is on Assumptions.
A23: THE THREE RULES A PACKAGE NEEDS
A24: Rule | B24: Setting | D24: Why it exists
A25: Expiry on unused hours | B25: 12 months | D25: Unused hours cannot sit on the books forever — they are a liability and they distort the earnings ledger.
A26: Partial refund basis — student cancels | B26: =Assumptions!$B$104 -> Amount paid less hours used at the full rate | D26: v4 CORRECTED. Refund = amount paid less hours used at the FULL rate. The student forfeits the pack discount on the hours they consumed, and the refund can never exceed what they paid.
A27: Which tier applies | B27: Set at purchase | D27: Package hours count toward the tutor's cumulative total, but the take rate is fixed at the moment of purchase, not re-evaluated per lesson.
A28: If the tutor becomes unavailable | B28: =Assumptions!$B$105 -> All unused hours at the rate actually paid | D28: v4 NEW — rule 4. All unused hours refunded at the rate the student actually paid, and TrioEdX absorbs the processing. Our fault, so the student keeps the discount they bought.
A29: • Only ONE package size is offered — 10 hours. No 5-pack, no 20-pack. One extra choice on the booking screen, not three.
A30: • The package is the retention mechanic: a student holding eight prepaid hours has already decided to come back. That is its whole purpose.
A32: WHAT THE REFUND ACTUALLY COSTS [NEW IN v4]
A33: Amount paid for the 10-hour pack | B33: =$B$4*10*(1-Assumptions!$B$59) -> 285 | E33: At the tutor rate in B4.
A34: Rate the student actually paid, per hour | B34: =$B$33/10 -> 28.5
A36: Hours used | B36: Rule 4 refund — tutor unavailable | C36: Refund if a student cancels | D36: As worded: unused hrs x UNDISCOUNTED rate | E36: Cash kept under that wording
A37: 0 | B37: =(10-$A37)*$B$34 -> 285 | C37: =MAX(0,$B$33-$A37*$B$4) -> 285 | D37: =(10-$A37)*$B$4 -> 300 | E37: =$B$33-$D37 -> -15
A38: 1 | B38: =(10-$A38)*$B$34 -> 256.5 | C38: =MAX(0,$B$33-$A38*$B$4) -> 255 | D38: =(10-$A38)*$B$4 -> 270 | E38: =$B$33-$D38 -> 15
A39: 4 | B39: =(10-$A39)*$B$34 -> 171 | C39: =MAX(0,$B$33-$A39*$B$4) -> 165 | D39: =(10-$A39)*$B$4 -> 180 | E39: =$B$33-$D39 -> 105
A40: 9 | B40: =(10-$A40)*$B$34 -> 28.5 | C40: =MAX(0,$B$33-$A40*$B$4) -> 15 | D40: =(10-$A40)*$B$4 -> 30 | E40: =$B$33-$D40 -> 255
A41: Processing TrioEdX absorbs on the original charge | B41: =$B$33*Assumptions!$C$25+Assumptions!$B$9 -> 12.555
A43: • Read the last column. 'Remaining hours refunded in full at the UNDISCOUNTED rate' pays out more than the student ever paid:
A44: at zero hours used, a 10-pack bought at 5% off is refunded at 100% of list, so the cash kept is NEGATIVE. Scale it up and a
A45: $40/hr tutor leaving before lesson one costs $20 on top of the processing absorbed.
A46: • Column B is the rule as built: unused hours at the rate the student actually paid. Same promise to the student, no leak.
A47: • Three things rule 4 still needs before it is enforceable, and none of them is a pricing decision:
A48: 1. A definition of 'unavailable' — two no-shows, seven days without a reply, account deactivated, or removed for cause.
...

Sheet Group Classes
A1: Group Class Economics
A2: One seat price everywhere. No minimum seat count — see the accepted risk below.
A4: Price per seat, per session | B4: 12 | F4: From the Price List.
A5: Sessions in the cohort | B5: 8 | F5: A cohort, not a one-off.
A6: Minimum seats to run | B6: 1 | F6: No minimum. Unchanged in v3 by decision.
A8: Seats | B8: Cohort revenue | C8: Net Revenue | D8: Tutor keeps | E8: TrioEdX net | F8: Tutor $ / teaching hour
A9: 1 | B9: =A9*$B$4*$B$5 -> 96 | C9: =B9-B9*Assumptions!$B$17-(B9*Assumptions!$C$25+Assumptions!$B$9*A9) -> 83.892 | D9: =C9*(1-Assumptions!$B$60) -> 65.43576 | E9: =C9*Assumptions!$B$60-B9*Assumptions!$C$34 -> 9.81624 | F9: =D9/$B$5 -> 8.17947
A10: 2 | B10: =A10*$B$4*$B$5 -> 192 | C10: =B10-B10*Assumptions!$B$17-(B10*Assumptions!$C$25+Assumptions!$B$9*A10) -> 167.784 | D10: =C10*(1-Assumptions!$B$60) -> 130.87152 | E10: =C10*Assumptions!$B$60-B10*Assumptions!$C$34 -> 19.63248 | F10: =D10/$B$5 -> 16.35894
A11: 3 | B11: =A11*$B$4*$B$5 -> 288 | C11: =B11-B11*Assumptions!$B$17-(B11*Assumptions!$C$25+Assumptions!$B$9*A11) -> 251.676 | D11: =C11*(1-Assumptions!$B$60) -> 196.30728 | E11: =C11*Assumptions!$B$60-B11*Assumptions!$C$34 -> 29.44872 | F11: =D11/$B$5 -> 24.53841
A12: 4 | B12: =A12*$B$4*$B$5 -> 384 | C12: =B12-B12*Assumptions!$B$17-(B12*Assumptions!$C$25+Assumptions!$B$9*A12) -> 335.568 | D12: =C12*(1-Assumptions!$B$60) -> 261.74304 | E12: =C12*Assumptions!$B$60-B12*Assumptions!$C$34 -> 39.26496 | F12: =D12/$B$5 -> 32.71788
A13: 6 | B13: =A13*$B$4*$B$5 -> 576 | C13: =B13-B13*Assumptions!$B$17-(B13*Assumptions!$C$25+Assumptions!$B$9*A13) -> 503.352 | D13: =C13*(1-Assumptions!$B$60) -> 392.61456 | E13: =C13*Assumptions!$B$60-B13*Assumptions!$C$34 -> 58.89744 | F13: =D13/$B$5 -> 49.07682
A14: 8 | B14: =A14*$B$4*$B$5 -> 768 | C14: =B14-B14*Assumptions!$B$17-(B14*Assumptions!$C$25+Assumptions!$B$9*A14) -> 671.136 | D14: =C14*(1-Assumptions!$B$60) -> 523.48608 | E14: =C14*Assumptions!$B$60-B14*Assumptions!$C$34 -> 78.52992 | F14: =D14/$B$5 -> 65.43576
A15: 10 | B15: =A15*$B$4*$B$5 -> 960 | C15: =B15-B15*Assumptions!$B$17-(B15*Assumptions!$C$25+Assumptions!$B$9*A15) -> 838.92 | D15: =C15*(1-Assumptions!$B$60) -> 654.3576 | E15: =C15*Assumptions!$B$60-B15*Assumptions!$C$34 -> 98.1624 | F15: =D15/$B$5 -> 81.7947
A16: 12 | B16: =A16*$B$4*$B$5 -> 1152 | C16: =B16-B16*Assumptions!$B$17-(B16*Assumptions!$C$25+Assumptions!$B$9*A16) -> 1006.704 | D16: =C16*(1-Assumptions!$B$60) -> 785.22912 | E16: =C16*Assumptions!$B$60-B16*Assumptions!$C$34 -> 117.79488 | F16: =D16/$B$5 -> 98.15364
A17: 15 | B17: =A17*$B$4*$B$5 -> 1440 | C17: =B17-B17*Assumptions!$B$17-(B17*Assumptions!$C$25+Assumptions!$B$9*A17) -> 1258.38 | D17: =C17*(1-Assumptions!$B$60) -> 981.5364 | E17: =C17*Assumptions!$B$60-B17*Assumptions!$C$34 -> 147.2436 | F17: =D17/$B$5 -> 122.69205
A18: 20 | B18: =A18*$B$4*$B$5 -> 1920 | C18: =B18-B18*Assumptions!$B$17-(B18*Assumptions!$C$25+Assumptions!$B$9*A18) -> 1677.84 | D18: =C18*(1-Assumptions!$B$60) -> 1308.7152 | E18: =C18*Assumptions!$B$60-B18*Assumptions!$C$34 -> 196.3248 | F18: =D18/$B$5 -> 163.5894
A20: ACCEPTED OPEN RISK — no-minimum seat count
A21: • A cohort runs with one student. At one seat the tutor earns far less per teaching hour than from a private lesson at the same time.
A22: • A top-up mitigation (paying the tutor the difference up to their private rate, capped) was proposed and DECLINED in v3. No mitigation is in place.
A23: • Consequence to watch: tutors who list a group class and do not fill it are worse off than if they had taught privately. Expect group-class listings to decline once tutors notice.
A24: • Logged here so the decision is visible and revisitable, not lost. Revisit if group-class listings fall or tutors raise it.
A26: Cohort rules that DO stand
A27: • Tutor is paid on seats present at session one, not reduced by later drops.
A28: • Late enrolment after session two is prorated on remaining sessions.
A29: • Show the seat count before purchase, so a student choosing a nearly-empty cohort is choosing it knowingly.

Sheet Courses
A1: Self-Paced Course Revenue Share
A2: Four channels, split on Net Revenue. Referral raised to 18% in v3.
A4: Course price (tax-inclusive) | B4: ='Price List'!B6 -> 79
A5: Net Revenue | B5: =B4-B4*Assumptions!$B$17-(B4*Assumptions!$B$25+Assumptions!$B$9) -> 68.667
A7: Acquisition channel | B7: TrioEdX take | C7: Instructor keeps % | D7: Instructor $ | E7: TrioEdX share $ | F7: TrioEdX net $ | G7: Note
A8: Instructor's own coupon / referral link | B8: =Assumptions!$B$61 -> 0.18 | C8: =1-B8 -> 0.82 | D8: =$B$5*C8 -> 56.30694 | E8: =$B$5*B8 -> 12.36006 | F8: =E8-$B$4*Assumptions!$B$34 -> 4.06506 | G8: v3: raised from 15% to 18%. At 15% it lost money at ANY price; at 18% on the Net Revenue basis it breaks even around $1, so every course on the list clears comfortably.
A9: TrioEdX organic marketplace / SEO | B9: =Assumptions!$B$62 -> 0.5 | C9: =1-B9 -> 0.5 | D9: =$B$5*C9 -> 34.3335 | E9: =$B$5*B9 -> 34.3335 | F9: =E9-$B$4*Assumptions!$B$34 -> 26.0385 | G9: Udemy pays the instructor 37% of a smaller base. 50% of Net Revenue is still the loudest recruiting number.
A10: TrioEdX paid acquisition | B10: =Assumptions!$B$63 -> 0.7 | C10: =1-B10 -> 0.3 | D10: =$B$5*C10 -> 20.6001 | E10: =$B$5*B10 -> 48.0669 | F10: =E10-$B$4*Assumptions!$B$34 -> 39.7719 | G10: TrioEdX carries CAC and refund risk; the instructor takes no discount. v5 NOTE (not modelled): the figure in F10 — currently $39.77 — is the CAC CEILING for this channel. Spend more than that to win the sale and it loses money. Above $13.73 of ad cost this channel earns less than the 50% organic row. CAC is deliberately not modelled yet.
A11: Commissioned degree course | B11: =Assumptions!$B$64 -> 0.6 | C11: =1-B11 -> 0.4 | D11: =$B$5*C11 -> 27.4668 | E11: =$B$5*B11 -> 41.2002 | F11: =E11-$B$4*Assumptions!$B$34 -> 32.9052 | G11: Alternative: a flat $2,000-5,000 build fee plus 10% royalty, with TrioEdX owning the IP.
A14: THE DISCOUNTING RULE [UPDATED IN v3 — closes audit issue 5]
A15: • No Udemy-style permanent 90%-off sales. They train the market never to pay list price.
A16: • Maximum 30% off list, capped at four promotional windows a year.
A17: • Instructors may discount to 50% with their own coupons.
A18: • v3 RULE: the platform fee is charged on the PRE-DISCOUNT amount. An instructor who issues a coupon funds it entirely from their own share, as the rule always intended.
A19: • Build note: Tutor LMS calculates on the post-discount order total by default, so this needs a filter on the earning calculation. Verify on staging before issuing any coupon.
A20: • Show the instructor a line on their earnings screen reading 'coupon discount, funded by you', so the number is never a surprise.

Sheet Subscription
A1: Subscription
A2: Pooled payout across opted-in self-paced courses only. See 'Subscription Scope'.
A4: Subscribers — monthly plan (6-month term) | B4: 900
A5: Subscribers — annual plan | B5: 600
A6: Monthly price | B6: ='Price List'!B12 -> 19
A7: Annual price | B7: ='Price List'!B13 -> 180
A9: Line | B9: Amount | E9: Note
A10: Gross monthly subscription revenue | B10: =B4*B6+B5*B7/12 -> 26100
A11: Less: tax | B11: =-B10*Assumptions!$B$17 -> -2088
A12: Less: processing | B12: =-(B10*Assumptions!$B$25+(B4/Assumptions!$B$73+B5/12)*Assumptions!$B$9) -> -1286.7 | E12: v4: monthly-plan subscribers are now billed ONCE per 6-month term, not every month. Fixed fees fall from one per subscriber per month to one per six.
A13: Net subscription revenue | B13: =SUM(B10:B12) -> 22725.3
A14: Less: TrioEdX's own costs | B14: =-B10*Assumptions!$B$34 -> -2740.5
A15: Instructor pool (share of Net Revenue) | B15: =B13*Assumptions!$B$65 -> 11362.65 | E15: Udemy allocates 15%. Guaranteed in writing not to fall for a course already opted in.
A16: TrioEdX retains, after own costs | B16: =B13-B15+B14 -> 8622.15
A18: POOL ALLOCATION — worked example
A19: Instructor | B19: Qualified minutes | C19: Share | D19: Payout | E19: Note
A20: Instructor A | B20: 420000 | C20: =IF($B$24=0,0,B20/$B$24) -> 0.35 | D20: =$B$15*C20 -> 3976.9275
A21: Instructor B | B21: 260000 | C21: =IF($B$24=0,0,B21/$B$24) -> 0.21666667 | D21: =$B$15*C21 -> 2461.9075
A22: Instructor C | B22: 180000 | C22: =IF($B$24=0,0,B22/$B$24) -> 0.15 | D22: =$B$15*C22 -> 1704.3975
A23: All others | B23: 340000 | C23: =IF($B$24=0,0,B23/$B$24) -> 0.28333333 | D23: =$B$15*C23 -> 3219.4175
A24: Total qualified minutes | B24: =SUM(B20:B23) -> 1200000 | D24: =SUM(D20:D23) -> 11362.65
A26: Effective rate per 1,000 qualified minutes | B26: =IF($B$24=0,0,$B$15/$B$24*1000) -> 9.468875 | E26: Publish monthly. This is the number the opt-in screen shows.
A28: ANTI-GAMING RULES
A29: • Only minutes after the first 5 minutes of a lesson count.
A30: • Cap any single instructor at 25% of the monthly pool; the excess redistributes.
A31: • Quiz, lab and assessment time counts; idle video with no interaction does not.
A32: • Minutes from an account that refunds in the same month are voided.
A33: • A course must hold a 4.0+ rating with 20+ reviews to draw from the pool.
A34: • Free courses are excluded from the pool entirely.
A36: MINIMUM TERM [NEW IN v4 — closes audit issue 1]
A37: Option | B37: Committed spend | C37: In standard courses | D37: Verdict
A38: No minimum (v3) | B38: ='Price List'!$B$12*1 -> 19 | C38: =B38/'Price List'!$B$6 -> 0.24050633 | E38: Cheaper than a single course. Every one-course buyer should subscribe instead — the catalogue is cannibalised.
A39: 3-month minimum | B39: ='Price List'!$B$12*3 -> 57 | C39: =B39/'Price List'!$B$6 -> 0.72151899 | E39: Still cheaper than a single course. Reduces the leak; does not close it.
A40: 6-month minimum (v4 — chosen) | B40: ='Price List'!$B$12*Assumptions!$B$73 -> 114 | C40: =B40/'Price List'!$B$6 -> 1.443038 | E40: Clears one course price with room. One or two courses stay cheaper bought outright; three or more favour the plan.
A41: Annual plan | B41: ='Price List'!$B$13 -> 180 | C41: =B41/'Price List'!$B$6 -> 2.278481 | E41: The healthiest ratio, and one charge a year.
A43: The rule: committed spend must exceed one standard course price, or the subscription competes with the catalogue instead of feeding it.
A45: BILLING THE TERM
A46: Line | B46: v3 — monthly billing | C46: v4 — one charge per term | D46: Difference
A47: Charges per monthly subscriber per year | B47: =12 -> 12 | C47: =12/Assumptions!$B$73 -> 2 | D47: =C47-B47 -> -10
A48: Fixed fees per subscriber per year | B48: =B47*Assumptions!$B$9 -> 3.6 | C48: =C47*Assumptions!$B$9 -> 0.6 | D48: =C48-B48 -> -3 | E48: Ten fewer fixed fees a year per subscriber.
...

Sheet Books & Authors
A1: Author Compensation
A2: Two routes, split on Net Revenue. [v5: print-on-demand and bundled-book routes removed.]
A4: Ebook list price (tax-inclusive) | B4: 24.99
A8: Route | B8: Author gets | C8: Net Revenue | D8: Author $ | E8: TrioEdX net $ | F8: When to use it
A9: 1. Ebook sold on TrioEdX | B9: =1-Assumptions!$B$66 -> 0.7 | C9: =$B$4-$B$4*Assumptions!$B$17-($B$4*Assumptions!$B$25+Assumptions!$B$9) -> 21.51627 | D9: =C9*B9 -> 15.061389 | E9: =C9*Assumptions!$B$66-$B$4*Assumptions!$B$34 -> 3.830931 | F9: Matches KDP's 70% author share with no $9.99 ceiling and no per-MB delivery fee.
A10: 2. Commissioned textbook (work-for-hire) | B10: fee + 10% | D10: 3000 | F10: $1,500-5,000 up front plus a 10% royalty. The only route that works for accredited curriculum.
A14: Author breakeven — units to match a $3,000 commission
A15: Ebook units to match a $3,000 commission | B15: =IF(D9=0,"n/a",3000/D9) -> 199.18482
A18: v5 CHANGES
A19: • Removed route 2, print-on-demand. Students are not offered printed books, so the print list price and the
A20: per-unit print cost have gone with it. This also removes physical fulfilment, returns and inventory from the model.
A21: • Removed route 3, book bundled into a course. A book is bought separately. This closes a real defect: the 8% royalty
A22: was charged on the COURSE's Net Revenue and was not allocated to anyone, so it came out of TrioEdX's share. On the
A23: instructor-referral channel that took the course from +$4.07 to -$1.43 — every referred sale with a bundled book lost money.
A24: • The print-on-demand lever on Assumptions is marked 'not offered' rather than deleted, so no cross-sheet reference breaks.

Sheet Take Rate Compare
A1: 10% vs 20% vs 30% — Against the Real Cost Base
A2: Take rates now apply to Net Revenue.
A4: Monthly gross transaction value (GTV) | B4: 40000
A5: Average ticket size | B5: 34
A6: Transactions per month | B6: =IF($B$5=0,0,$B$4/$B$5) -> 1176.4706
A7: Monthly Net Revenue | B7: =$B$4-$B$4*Assumptions!$B$17-($B$4*Assumptions!$B$25+$B$6*Assumptions!$B$9) -> 34567.059
A9: Metric | B9: 10% take | C9: 20% take | D9: 30% take | F9: Note
A10: Take rate (of Net Revenue) | B10: 0.1 | C10: 0.2 | D10: 0.3
A11: TrioEdX share of Net Revenue | B11: =$B$7*B10 -> 3456.7059 | C11: =$B$7*C10 -> 6913.4118 | D11: =$B$7*D10 -> 10370.118
A12: Less: TrioEdX's own costs | B12: =-$B$4*Assumptions!$B$34 -> -4200 | C12: =-$B$4*Assumptions!$B$34 -> -4200 | D12: =-$B$4*Assumptions!$B$34 -> -4200
A13: Contribution margin | B13: =B11+B12 -> -743.29412 | C13: =C11+C12 -> 2713.4118 | D13: =D11+D12 -> 6170.1176
A14: Less: fixed cost | B14: =-Assumptions!$B$49 -> -3374.5 | C14: =-Assumptions!$B$49 -> -3374.5 | D14: =-Assumptions!$B$49 -> -3374.5
A15: Operating profit / (loss) | B15: =B13+B14 -> -4117.7941 | C15: =C13+C14 -> -661.08824 | D15: =D13+D14 -> 2795.6176
A17: RECOMMENDED STRUCTURE (current)
A18: Line | B18: Rate | C18: Nearest competitor | D18: Their take | F18: Why
A19: 1-on-1, hours 0-50 | B19: =Assumptions!$B$53 -> 0.25 | C19: Preply tier 1 | D19: 0.33 | F19: Undercut visibly from the first hour.
A20: 1-on-1, hours 51-300 | B20: =Assumptions!$B$54 -> 0.2 | C20: Preply tier 2 | D20: 0.28 | F20: Rewards retention without gutting margin.
A21: 1-on-1, hours 300+ (flat) | B21: =Assumptions!$B$55 -> 0.17 | C21: Preply tier 3 | D21: 0.18 | F21: v5: flat 17%. Beats Preply's 18% floor at every rate, with no conditional branch.
A23: 10-hour package | B23: =Assumptions!$B$59 -> 0.05 | C23: italki packages | F23: 5% off, funded by the fixed-fee saving.
A24: Group classes | B24: =Assumptions!$B$60 -> 0.22 | C24: Outschool | D24: 0.3 | F24: Group pays the tutor more per hour once it fills.
A25: Course — instructor referred | B25: =Assumptions!$B$61 -> 0.18 | C25: Udemy coupon | D25: 0.03 | F25: v3: 18%. Clears cost at every price on the list.
A26: Course — TrioEdX organic | B26: =Assumptions!$B$62 -> 0.5 | C26: Udemy organic | D26: 0.63 | F26: The loudest instructor-recruiting number.
A27: Subscription pool | B27: =Assumptions!$B$65 -> 0.5 | C27: Udemy pool | D27: 0.15 | F27: Now scoped to opted-in self-paced courses only.
A28: Ebook | B28: =Assumptions!$B$66 -> 0.3 | C28: Amazon KDP | D28: 0.3 | F28: Matches the 70% author share authors anchor on.

Sheet Benchmarks
A1: Sourced Benchmarks
A2: Verified August-September 2026.
A4: Platform | B4: What they take / pay | C4: Category | D4: Source
A5: Preply | B5: 33% (0-20 hrs) / 28% (20+) / 18% (400+); 100% of every trial lesson | C5: 1-on-1 | D5: help.preply.com/en/articles/4171383-preply-commission-model
A6: Preply cancellations | B6: Cancel >12h ahead and the lesson returns to balance; inside 12h the tutor is paid | C6: Cancellation | D6: help.preply.com/en/articles/4179413-cancellation-policy-for-students
A7: italki | B7: ~21% on single 1:1 lessons, lower on prepaid packages; ~30% group. Community-reported. | C7: Packages | D7: pensight.com/post/italki-commission-teachers
A8: Wyzant | B8: 25% platform fee | C8: 1-on-1 | D8: supatutor.in/how-much-does-wyzant-take-from-tutors/
A9: Outschool | B9: 30% take rate; teacher receives 70% of class price | C9: Group classes | D9: support.outschool.com/en/articles/2382129-teacher-earnings-and-payments-policy
A10: Udemy | B10: 97% on own coupon/referral; 37% on Udemy organic; 80% on Connect 1:1 coaching | C10: Courses | D10: support.udemy.com/hc/en-us/articles/229605008-Instructor-revenue-share
A11: Udemy Business | B11: 15% of subscription revenue forms the instructor pool, split by minutes consumed | C11: Subscription | D11: support.udemy.com/hc/en-us/articles/115013221767
A12: Udemy refunds | B12: 30-day window; instructors paid after it closes, so the delay enforces the policy | C12: Refunds | D12: support.udemy.com/hc/en-us/articles/360050856093-Udemy-s-Refund-Policy
A13: Amazon KDP | B13: 70% ebook royalty at $2.99-$9.99 less $0.15/MB; print = 60% of list less print cost | C13: Books | D13: kdpeasy.com/guides/2026-kdp-royalty-rates
A14: Online tutoring rates | B14: Median EUR 25/hr math & English; EUR 28-30 CS and programming | C14: Rate benchmark | D14: itutoronline.com/research/online-tutoring-rates-2026
A15: US online associate degrees | B15: $1,380-$5,220/yr among the cheapest; median $3,330/yr | C15: Degree pricing | D15: onlineu.com/most-affordable-colleges/associate-degrees
... A19: Wise vs Payoneer (PK) | B19: Wise ~0.4-0.7%; Payoneer ~2% into PKR. Stripe does not pay out to Pakistan. | C19: Payout cost | D19: xpezia.com.pk/blog/payoneer-vs-wise-pakistan-best-payment-platform-for-freelancers-2026/

Sheet Refunds & Payouts
A1: Refunds, Cancellation & Payout Hold [NEW IN v4]
A2: One page covering all four revenue lines. v3 had no refund policy anywhere in the workbook.
A4: Revenue line | B4: Refund window | C4: Who bears the cost | D4: Payout released | E4: Rule
A5: Self-paced courses | B5: 30 days, no questions | C5: Instructor (unpaid) | D5: Day 31 | E5: The window closes before anyone is paid, so the refund costs the instructor their share and TrioEdX the processing.
A6: Professional certificate | B6: 30 days OR first assessment, whichever is first | C6: Instructor (unpaid) | D6: Day 31 | E6: Once assessed work has been submitted the credential process has begun and the sale stands.
A7: Associate-degree course | B7: 14 days from term start | C7: Shared | D7: Day 31 | E7: Academic drop windows are shorter than consumer ones and are set by the term calendar, not the purchase date.
A8: Group class / cohort | B8: Full before session 1; pro-rata to end of session 2; none after | C8: TrioEdX | D8: After session 2 | E8: v4 addition. The 12-hour rule cannot govern a multi-week cohort — the seat was held and the cohort was sized around it.
A9: 1-on-1 single lesson | B9: 12-hour cancellation rule | C9: Student inside 12h | D9: Day 31 (see warning) | E9: Cancel more than 12 hours ahead and the hour returns to the balance; inside 12 hours it is charged. Mirrors Preply.
A10: 1-on-1 10-hour pack — student cancels | B10: Any time, on unused hours | C10: Student forfeits the discount | D10: Day 31 | E10: Refund = amount paid less hours used at the FULL rate. Never exceeds what was paid.
A11: 1-on-1 10-hour pack — tutor unavailable | B11: Immediate, on unused hours | C11: TrioEdX | D11: n/a | E11: Rule 4. Unused hours at the rate actually paid, processing absorbed. Charged against the tutor's balance where one exists.
A12: Subscription term | B12: No refund of the current term | C12: n/a | D12: Monthly pool | E12: Cancelling stops the next renewal. The 30-day course window must NOT apply here or the 6-month minimum is unenforceable. EU/UK buyers keep a 14-day withdrawal right unless they consent to immediate access at checkout.
A13: Books / ebooks | B13: 30 days | C13: Author (unpaid) | D13: Day 31 | E13: Same shape as courses.
A15: THE TWO THINGS THAT COST MONEY
B16: Fact | E16: Consequence
A17: Processing fees are NOT returned on a refund | E17: WooPayments: 'the fees paid on that transaction are not refunded to your WooPayments account.' Every refunded $79 course is a $4.01 cash loss, not a wash. Test the 4% reserve on Assumptions B31 against actuals early — paid-acquisition traffic refunds well above organic.
A18: The payout hold is ONE global setting | E18: Tutor LMS's 'minimum days for balance to be available' cannot differ by product. Setting it to 30 to fund course refunds holds TUTOR money 30 days too, though a live session has only a 12-hour exposure. Preply confirms a classroom lesson about 15 minutes after it ends and the tutor withdraws immediately. This is a tutor-recruitment problem, not an accounting one.
A20: OPTIONS ON THE PAYOUT HOLD — pick one before launch
A21: A. Accept 30 days globally. Free. State it plainly on the tutor signup page rather than letting tutors discover it.
A22: B. Set the global hold to 3 days for live work and hold course earnings by a separate mechanism. Custom code — add to the
A23: dev-day count in the WooCommerce build model.
A24: C. Two payout tracks, per product type. The cleanest and the most expensive.
A25: Recommendation: A at launch, B once tutor supply becomes the constraint. Do not discover this after signing 50 tutors.
A27: BUILD NOTES
A28: • Tutor LMS: Settings > Monetization > 'Minimum days for balance to be available' = 30.
A29: • The 30-day window must be excluded for subscription terms in WooCommerce Subscriptions, or the minimum term is void.
A30: • Group-class pro-rata refunds need a per-session completion flag; Tutor LMS has no cohort progress concept. Custom code.
A31: • Package refunds need an unused-hours ledger per student per tutor. Custom code, and it is the same ledger rule 4 depends on.
A34: SOURCES
... A38: Udemy — refund policy: support.udemy.com/hc/en-us/articles/360050856093-Udemy-s-Refund-Policy

Sheet Change Log
A1: v5 Change Log
A2: Books simplified, tier 3 flattened to 17%, and the break-even block rewritten to show contribution.
A3: Date & Time update: 2026/09/07 23:54
A4: S.I. | B4: Issue raised against v4 | C4: Where changed | D4: What was done
A5: 1 | B5: Print-on-demand route not offered to students | C5: Books & Authors 5, 6, 10, 16; Assumptions 67 | D5: Route 2 (print-on-demand) removed, with the print list price, per-unit print cost and print break-even. The Assumptions lever is marked 'not offered' rather than deleted, so the references below it stay valid. Removes physical fulfilment, returns and inventory from the model.
A6: 2 | B6: Bundled-book royalty was unallocated and lost money | C6: Books & Authors 11 | D6: Route 3 (book bundled into a course) removed; a book is bought separately. This closes the worst defect in v4: the 8% royalty was charged on the COURSE's Net Revenue and belonged to nobody, so it came out of TrioEdX's share. On the instructor-referral channel it took a sale from +$4.07 to -$1.43. Books now has two routes: ebook, and commissioned textbook.
A7: 3 | B7: No CAC anywhere in the model | C7: Courses G10 — note only | D7: DEFERRED by decision. A note records that TrioEdX net on the paid-acquisition row ($39.77) is that channel's CAC ceiling, and that above $13.73 of ad cost it earns less than the organic row. Nothing is modelled.
A8: 4 | B8: Tier 3 conditional on an $18/hr floor | C8: Assumptions 55-57; 1-on-1 Tutoring 11-18, 23; Take Rate Compare 21-22 | D8: Tier 3 is now a FLAT 17%. The floor and the 20% below-floor branch are retired. The floor rested on a $17.65/hr break-even carried over from v2's gross-price basis; on Net Revenue 17% breaks even near $0.86/hr, so the whole band is profitable. At $30/hr TrioEdX keeps $1.72 (5.7%) instead of $1.20 (4.0%).
A9: 5 | B9: Group-class seat economics | C9: — | D9: IGNORED by decision. One seat still pays the tutor $8.18 per teaching hour against $21.59 on 1-on-1 tier 3; three seats is where a cohort becomes worth a tutor's time. Logged as an accepted open risk.
A10: 6 | B10: 'Minimum viable price' read as a pricing floor | C10: Payment Economics 14-29 | D10: Retitled as variable-cost break-even, with contribution per transaction and the sales-per-month needed to cover fixed cost beside it. The break-even figure alone said a $1 course was viable; the contribution column says what a sale is worth.
A11: 7 | B11: No cap on trial lessons per student | C11: — | D11: IGNORED by decision. Logged as an accepted open risk.
A13: STILL OPEN AFTER v5
A14: • Nothing in the workbook recovers the $3,374/month fixed cost, and Take Rate Compare still models flat 10/20/30% takes
A15: that the model no longer uses. Its headline conclusion tests a business TrioEdX does not run. Needs a blended-mix P&L.
A16: • Declined and logged: certificate vs its component courses; tier-3 floor vs the pack discount (now moot); group-class
A17: no-minimum seat count; no trial-lesson cap; CAC not modelled.
A18: • Tutor LMS supports ONE global commission percentage and ONE global payout hold — the ladder, the channel split, the
A19: per-product hold and the package hours ledger all still need custom code.
A20: • The blended tax rate in Assumptions B17 is still an estimate. Replace it with Quaderno's actual figure.
A21: • The associate degree is still not priced per credit — see the Action Item tab.
A22: Four of the six issues raised against v3 were actioned. Two were declined by decision.
A23: Date & Time update: 2026/09/07 18:36
A24: S.I. | B24: Issue raised against v3 | C24: Where changed | D24: What was done
A25: 1 | B25: Monthly subscription cannibalised the catalogue | C25: Assumptions 71-78; Subscription 36-59; Price List | D25: 6-month minimum term, billed as ONE charge per term. $114 committed = 1.44 standard courses, so the plan no longer undercuts a single $79 course. Three months ($57) would not have cleared it. Subscription B12 now charges one fixed fee per term instead of twelve a year.
A26: 2 | B26: Certificate excluded but its component courses included | C26: — | D26: IGNORED by decision. A subscriber still reaches every component course of a $299 certificate for $180/yr and misses only the credential. Logged as an accepted open risk.
A27: 3 | B27: Tax rate squeezes margin twice | C27: Assumptions 80-91 | D27: Sensitivity table at 0 / 8 / 15 / 20% tax. Flagged for quarterly review against Quaderno's actual blended figure, and flagged as a live input to instructor payouts — actual per-transaction tax should drive the payout engine, not the blend.
A28: 4 | B28: $18 tier-3 floor collides with the 5% pack discount | C28: — | D28: IGNORED by decision. A tutor listing between $18.00 and $18.94/hr still has a 10-pack effective rate below the floor. Logged as an accepted open risk.
A29: 5 | B29: No refund policy anywhere in the workbook | C29: Assumptions 94-110; new tab 'Refunds & Payouts' | D29: 30-day course window, earnings released day 31, 12-hour live cancellation rule, Tutor LMS hold set to 30. Added the group-class withdrawal rule, which the recommendation did not cover, and the WooPayments fact that fees are not returned on a refund. Flagged that the 30-day hold is one global setting and delays tutors too.
A30: 6 | B30: No rule for prepaid hours when a tutor leaves | C30: Assumptions 104-105; Lesson Packages 26-49 | D30: Rule 4 added. CHANGED FROM THE WORDING PROPOSED: 'refunded in full at the undiscounted rate' pays out more than the student paid — a $25/hr 10-pack costs $237.50 and ten unused hours at $25 is $250. Built as unused hours at the rate actually paid, which keeps the student whole with no leak. The 'as worded' column on Lesson Packages shows the cost of the literal version so the change can be reversed knowingly.
A32: STILL OPEN AFTER v4
A33: • Issue 2 (certificate vs its component courses) and issue 4 (tier-3 floor vs the pack discount) — declined, logged.
A34: • Group class no-minimum risk — declined in v3, still open.
A35: • Tutor LMS supports ONE global commission percentage and ONE global payout hold. The tiered ladder, the channel split,
A36: the per-product payout hold and the package hours ledger all need custom code.
A37: • The blended tax rate in Assumptions B17 is still an estimate. Replace it with Quaderno's actual within the first quarter.
A38: • Rule 4 needs a written definition of 'tutor unavailable' before it can be enforced.
A39: • Nothing in this workbook prices the associate degree per credit. That sits on the Action Items tab as a critical item.
A42: v3 Change Log
A43: Every change, and the audit issue it closes.
A44: Date & Time update: 2026/09/07 18:31
...

Sheet Action Item
B1: Action Items | F1: {Please fill in} | G1: =COUNTIFS(G6:G2973,"{Please fill in}") -> 21
F2: In-Progress | G2: =COUNTIFS(G6:G2973,"In Progress*") -> 0
F3: Completed | G3: =COUNTIFS(G6:G2973,"Completed") -> 0
F4: Postponed | G4: =COUNTIFS(G6:G2973,"Postponed") -> 0
F5: ???? | G5: =COUNTIFS(G6:G2973,"????") -> 0
B6: Log Date | C6: Tasks / Activities / Action items | D6: Target Date | E6: Current Owner | F6: Priority | G6: Status | H6: Comments/Action Needed
B7: 46271 | C7: In future add the flat fee for $100/credit hours for ucjersey.com associate degress | F7: 1. Critical | G7: {Please fill in}
B8: 46271 | C8: Add zones at one point (file ref. with zone is "TrioEdX_Pricing_Revenue_Share_Model_WooCommerce v1.xlsx") | F8: 2. High | G8: {Please fill in}
F9: {Please fill in} | G9: {Please fill in}
F10: {Please fill in} | G10: {Please fill in}
F11: {Please fill in} | G11: {Please fill in}
F12: {Please fill in} | G12: {Please fill in}
F13: {Please fill in} | G13: {Please fill in}
F14: {Please fill in} | G14: {Please fill in}
F15: {Please fill in} | G15: {Please fill in}
F16: {Please fill in} | G16: {Please fill in}
F17: {Please fill in} | G17: {Please fill in}
F18: {Please fill in} | G18: {Please fill in}
F19: {Please fill in} | G19: {Please fill in}
F20: {Please fill in} | G20: {Please fill in}
... F27: {Please fill in} | G27: {Please fill in}
